Traceback (most recent call last):
  File "/usr/share/miniconda3/envs/ams-open-radar-2023-dev/lib/python3.11/site-packages/nbclient/client.py", line 778, in _async_poll_for_reply
    msg = await ensure_async(self.kc.shell_channel.get_msg(timeout=new_timeout))
          ^^^^^^^^^^^^^^^^^^^^^^^^^^^^^^^^^^^^^^^^^^^^^^^^^^^^^^^^^^^^^^^^^^^^^^
  File "/usr/share/miniconda3/envs/ams-open-radar-2023-dev/lib/python3.11/site-packages/jupyter_core/utils/__init__.py", line 182, in ensure_async
    result = await obj
             ^^^^^^^^^
  File "/usr/share/miniconda3/envs/ams-open-radar-2023-dev/lib/python3.11/site-packages/jupyter_client/channels.py", line 230, in get_msg
    raise Empty
_queue.Empty

During handling of the above exception, another exception occurred:

Traceback (most recent call last):
  File "/usr/share/miniconda3/envs/ams-open-radar-2023-dev/lib/python3.11/site-packages/jupyter_cache/executors/utils.py", line 58, in single_nb_execution
    executenb(
  File "/usr/share/miniconda3/envs/ams-open-radar-2023-dev/lib/python3.11/site-packages/nbclient/client.py", line 1305, in execute
    return NotebookClient(nb=nb, resources=resources, km=km, **kwargs).execute()
           ^^^^^^^^^^^^^^^^^^^^^^^^^^^^^^^^^^^^^^^^^^^^^^^^^^^^^^^^^^^^^^^^^^^^^
  File "/usr/share/miniconda3/envs/ams-open-radar-2023-dev/lib/python3.11/site-packages/jupyter_core/utils/__init__.py", line 166, in wrapped
    return loop.run_until_complete(inner)
           ^^^^^^^^^^^^^^^^^^^^^^^^^^^^^^
  File "/usr/share/miniconda3/envs/ams-open-radar-2023-dev/lib/python3.11/asyncio/base_events.py", line 653, in run_until_complete
    return future.result()
           ^^^^^^^^^^^^^^^
  File "/usr/share/miniconda3/envs/ams-open-radar-2023-dev/lib/python3.11/site-packages/nbclient/client.py", line 705, in async_execute
    await self.async_execute_cell(
  File "/usr/share/miniconda3/envs/ams-open-radar-2023-dev/lib/python3.11/site-packages/nbclient/client.py", line 1001, in async_execute_cell
    exec_reply = await self.task_poll_for_reply
                 ^^^^^^^^^^^^^^^^^^^^^^^^^^^^^^
  File "/usr/share/miniconda3/envs/ams-open-radar-2023-dev/lib/python3.11/site-packages/nbclient/client.py", line 802, in _async_poll_for_reply
    error_on_timeout_execute_reply = await self._async_handle_timeout(timeout, cell)
                                     ^^^^^^^^^^^^^^^^^^^^^^^^^^^^^^^^^^^^^^^^^^^^^^^
  File "/usr/share/miniconda3/envs/ams-open-radar-2023-dev/lib/python3.11/site-packages/nbclient/client.py", line 852, in _async_handle_timeout
    raise CellTimeoutError.error_from_timeout_and_cell(
nbclient.exceptions.CellTimeoutError: A cell timed out while it was being executed, after 1200 seconds.
The message was: Cell execution timed out.
Here is a preview of the cell contents:
-------------------
grids, params = pydda.retrieval.get_dd_wind_field([uah_grid, nexrad_grid], 
                                                  Co=0.1, Cm=1024.,
                                                  Cx=1e2, Cy=1e2, Cz=1e2, Cb=0,
                                                  frz=5000.0, filter_window=5,
                                                  mask_outside_opt=True, upper_bc=1,
                                                  vel_name='corrected_velocity',
                                                  wind_tol=0.5, engine="scipy")
-------------------

